<?xml version="1.0" ?>
<!-- =================================================================================== -->
<!-- |    This document was autogenerated by xacro from veerbhadra.xacro               | -->
<!-- |    EDITING THIS FILE BY HAND IS NOT RECOMMENDED                                 | -->
<!-- =================================================================================== -->
<robot name="veerbhadra">
  <!-- The Frame and its Joint with the World -->
  <link name="base">
    <visual>
      <origin xyz="0 0 0"/>
      <geometry>
        <box size="1.5 1.0 0.2"/>
      </geometry>
      <material name="white">
        <color rgba="1 1 1 1"/>
      </material>
    </visual>
    <collision>
      <origin xyz="0 0 0"/>
      <geometry>
        <box size="1.5 1.0 0.2"/>
      </geometry>
    </collision>
    <inertial>
      <origin xyz="0 0 0"/>
      <mass value="1.0"/>
      <inertia ixx="1.0" ixy="0.0" ixz="0.0" iyy="1.0" iyz="0.0" izz="1.0"/>
    </inertial>
  </link>
  <gazebo reference="base">
    <material>Gazebo/White</material>
  </gazebo>
  <!-- The Head and its Joint with the Frame -->
  <link name="head">
    <visual>
      <origin xyz="0 0 0.1"/>
      <geometry>
        <box size="0.2 0.2 0.2"/>
      </geometry>
      <material name="green">
        <color rgba="0 1 0 1"/>
      </material>
    </visual>
    <collision>
      <origin xyz="0 0 0.1"/>
      <geometry>
        <box size="0.2 0.2 0.2"/>
      </geometry>
    </collision>
    <inertial>
      <origin xyz="0 0 0.1"/>
      <mass value="1.0"/>
      <inertia ixx="1.0" ixy="0.0" ixz="0.0" iyy="1.0" iyz="0.0" izz="1.0"/>
    </inertial>
  </link>
  <joint name="head_joint" type="fixed">
    <origin xyz="0.65 0 0.1"/>
    <parent link="base"/>
    <child link="head"/>
  </joint>
  <gazebo reference="head">
    <material>Gazebo/Green</material>
  </gazebo>
  <!-- The Wheel macro -->
  <gazebo>
    <plugin name="differential_drive_controller" filename="libgazebo_ros_diff_drive.so">
      <update>100</update>
      <updateRate>100.0</updateRate>
      <leftJoint>lb_joint</leftJoint>
      <rightJoint>rb_joint</rightJoint>
      <wheelSeparation>0.6</wheelSeparation>
      <wheelDiameter>0.4</wheelDiameter>
      <torque>5</torque>
      <commandTopic>/veerbhadra/cmd_vel</commandTopic>
      <odometryTopic>/veerbhadra/odom</odometryTopic>
      <odometryFrame>base</odometryFrame>
      <robotBaseFrame>base</robotBaseFrame>
    </plugin>
  </gazebo>
  <!-- The IMU -->
  <joint name="imu_joint" type="fixed">
    <axis xyz="1 0 0"/>
    <origin xyz="0 0 0.15"/>
    <parent link="base"/>
    <child link="imu_link"/>
  </joint>
  <link name="imu_link">
    <inertial>
      <mass value="0.001"/>
      <origin rpy="0 0 0" xyz="0 0 0"/>
      <inertia ixx="0.0001" ixy="0" ixz="0" iyy="0.0001" iyz="0" izz="0.0001"/>
    </inertial>
    <visual>
      <origin rpy="0 0 0" xyz="0 0 0"/>
      <geometry>
        <box size="0.1 0.1 0.1"/>
      </geometry>
    </visual>
    <collision>
      <origin rpy="0 0 0" xyz="0 0 0"/>
      <geometry>
        <box size="0.1 0.1 0.1"/>
      </geometry>
    </collision>
  </link>
  <gazebo>
      <!--<sensor name="imu_sensor" type="imu">
      <imu>
          <noise>
              <type>gaussian</type>
              <rate>
                  <mean>0.0</mean>
                  <stddev>2e-4</stddev>
                  <bias_mean>0.0000075</bias_mean>
                  <bias_stddev>0.0000008</bias_stddev>
              </rate>
          </noise>
      </imu>-->
      <plugin name="imu_controller" filename="libgazebo_ros_imu.so">
          <topicName>/imu/data</topicName>
          <alwaysOn>true</alwaysOn>
          <updateRate>50.0</updateRate>
          <bodyName>imu_link</bodyName>
          <serviceName>/imu/calibrate</serviceName>
          <gaussianNoise>0.000002</gaussianNoise>
      </plugin>
      <!--</sensor>-->
  </gazebo>
  <!-- Front Camera -->
  <link name="front_cam_link">
    <inertial>
      <mass value="0.01"/>
      <origin rpy="0 1.57075 0" xyz="0 0 0"/>
      <inertia ixx="0.001" ixy="0.0" ixz="0.0" iyy="0.001" iyz="0.0" izz="0.001"/>
    </inertial>
    <visual>
      <origin rpy="0 1.57075 0" xyz="0 0 0"/>
      <geometry>
        <cylinder length="0.1" radius="0.1"/>
      </geometry>
    </visual>
    <collision>
      <origin rpy="0 1.57075 0" xyz="0 0 0"/>
      <geometry>
        <cylinder length="0.1" radius="0.1"/>
      </geometry>
    </collision>
  </link>
  <joint name="front_cam_joint" type="fixed">
    <origin rpy="0 0 0" xyz="0.75 0 0.2"/>
    <parent link="base"/>
    <child link="front_cam_link"/>
  </joint>
  <gazebo reference="front_cam_link">
    <sensor name="front_cam_sensor" type="camera">
      <camera name="front_camera">
          <horizontal_fov>1.57079</horizontal_fov>
          <image>
              <width>640</width>
              <height>480</height>
              <format>R8G8B8</format>
          </image>
          <clip>
              <near>0.01</near>
              <far>100</far>
          </clip>
          <noise>
              <type>gaussian</type>
              <mean>-0.2</mean>
              <stddev>0.1</stddev>
          </noise>
      </camera>
      <update_rate>20.0</update_rate>
      <plugin name="front_camera_controller" filename="libgazebo_ros_prosilica.so">
        <cameraName>front_camera</cameraName>
        <alwaysOn>true</alwaysOn>
        <updateRate>20.0</updateRate>
        <imageTopicName>/front_camera/image_raw</imageTopicName>
        <frameName>front_cam_link</frameName>
        <hackBaseline>0.07</hackBaseline>
      </plugin>
    </sensor>
    <turnGravityOff>true</turnGravityOff>
    <material value="Gazebo/Blue"/>
  </gazebo>
  <!-- Bottom Camera -->
  <link name="bottom_cam_link">
    <inertial>
      <mass value="0.01"/>
      <origin rpy="0 1.57075 0" xyz="0 0 0"/>
      <inertia ixx="0.001" ixy="0.0" ixz="0.0" iyy="0.001" iyz="0.0" izz="0.001"/>
    </inertial>
    <visual>
      <origin rpy="0 1.57075 0" xyz="0 0 0"/>
      <geometry>
        <cylinder length="0.1" radius="0.1"/>
      </geometry>
    </visual>
    <collision>
      <origin rpy="0 1.57075 0" xyz="0 0 0"/>
      <geometry>
        <cylinder length="0.1" radius="0.1"/>
      </geometry>
    </collision>
  </link>
  <joint name="bottom_cam_joint" type="fixed">
    <origin rpy="0 1.57075 0" xyz="0.65 0 -0.15"/>
    <parent link="base"/>
    <child link="bottom_cam_link"/>
  </joint>
  <gazebo reference="bottom_cam_link">
    <sensor name="bottom_cam_sensor" type="camera">
      <camera name="bottom_camera">
          <horizontal_fov>1.57079</horizontal_fov>
          <image>
              <width>640</width>
              <height>480</height>
              <format>R8G8B8</format>
          </image>
          <clip>
              <near>0.01</near>
              <far>100</far>
          </clip>
          <noise>
              <type>gaussian</type>
              <mean>-0.2</mean>
              <stddev>0.1</stddev>
          </noise>
      </camera>
      <update_rate>20.0</update_rate>
      <plugin name="bottom_camera_controller" filename="libgazebo_ros_prosilica.so">
        <cameraName>bottom_camera</cameraName>
        <alwaysOn>true</alwaysOn>
        <updateRate>20.0</updateRate>
        <imageTopicName>/bottom_camera/image_raw</imageTopicName>
        <frameName>bottom_cam_link</frameName>
        <hackBaseline>0.07</hackBaseline>
      </plugin>
    </sensor>
    <turnGravityOff>true</turnGravityOff>
    <material value="Gazebo/Blue"/>
  </gazebo>
  <!-- use the Wheel xacro to create the wheels -->
  <link name="lf_link">
    <visual>
      <origin rpy="1.57075 0 0" xyz="0 0 0"/>
      <geometry>
        <cylinder length="0.1" radius="0.2"/>
      </geometry>
      <material name="red">
        <color rgba="1 0 0 1"/>
      </material>
    </visual>
    <collision>
      <origin rpy="1.57075 0 0" xyz="0 0 0"/>
      <geometry>
        <cylinder length="0.1" radius="0.2"/>
      </geometry>
    </collision>
    <inertial>
      <mass value="1.0"/>
      <inertia ixx="1.0" ixy="0.0" ixz="0.0" iyy="1.0" iyz="0.0" izz="1.0"/>
    </inertial>
  </link>
  <gazebo reference="lf_link">
    <material>Gazebo/Red</material>
    <mu1 value="1.0"/>
    <mu2 value="1.0"/>
  </gazebo>
  <joint name="lf_joint" type="continuous">
    <axis xyz="0 1 0"/>
    <origin xyz="0.6 0.6 -0.5"/>
    <parent link="base"/>
    <child link="lf_link"/>
  </joint>
  <link name="lb_link">
    <visual>
      <origin rpy="1.57075 0 0" xyz="0 0 0"/>
      <geometry>
        <cylinder length="0.1" radius="0.2"/>
      </geometry>
      <material name="red">
        <color rgba="1 0 0 1"/>
      </material>
    </visual>
    <collision>
      <origin rpy="1.57075 0 0" xyz="0 0 0"/>
      <geometry>
        <cylinder length="0.1" radius="0.2"/>
      </geometry>
    </collision>
    <inertial>
      <mass value="1.0"/>
      <inertia ixx="1.0" ixy="0.0" ixz="0.0" iyy="1.0" iyz="0.0" izz="1.0"/>
    </inertial>
  </link>
  <gazebo reference="lb_link">
    <material>Gazebo/Red</material>
    <mu1 value="1.0"/>
    <mu2 value="1.0"/>
  </gazebo>
  <joint name="lb_joint" type="continuous">
    <axis xyz="0 1 0"/>
    <origin xyz="-0.6 0.6 -0.5"/>
    <parent link="base"/>
    <child link="lb_link"/>
  </joint>
  <link name="rf_link">
    <visual>
      <origin rpy="1.57075 0 0" xyz="0 0 0"/>
      <geometry>
        <cylinder length="0.1" radius="0.2"/>
      </geometry>
      <material name="red">
        <color rgba="1 0 0 1"/>
      </material>
    </visual>
    <collision>
      <origin rpy="1.57075 0 0" xyz="0 0 0"/>
      <geometry>
        <cylinder length="0.1" radius="0.2"/>
      </geometry>
    </collision>
    <inertial>
      <mass value="1.0"/>
      <inertia ixx="1.0" ixy="0.0" ixz="0.0" iyy="1.0" iyz="0.0" izz="1.0"/>
    </inertial>
  </link>
  <gazebo reference="rf_link">
    <material>Gazebo/Red</material>
    <mu1 value="1.0"/>
    <mu2 value="1.0"/>
  </gazebo>
  <joint name="rf_joint" type="continuous">
    <axis xyz="0 1 0"/>
    <origin xyz="0.6 -0.6 -0.5"/>
    <parent link="base"/>
    <child link="rf_link"/>
  </joint>
  <link name="rb_link">
    <visual>
      <origin rpy="1.57075 0 0" xyz="0 0 0"/>
      <geometry>
        <cylinder length="0.1" radius="0.2"/>
      </geometry>
      <material name="red">
        <color rgba="1 0 0 1"/>
      </material>
    </visual>
    <collision>
      <origin rpy="1.57075 0 0" xyz="0 0 0"/>
      <geometry>
        <cylinder length="0.1" radius="0.2"/>
      </geometry>
    </collision>
    <inertial>
      <mass value="1.0"/>
      <inertia ixx="1.0" ixy="0.0" ixz="0.0" iyy="1.0" iyz="0.0" izz="1.0"/>
    </inertial>
  </link>
  <gazebo reference="rb_link">
    <material>Gazebo/Red</material>
    <mu1 value="1.0"/>
    <mu2 value="1.0"/>
  </gazebo>
  <joint name="rb_joint" type="continuous">
    <axis xyz="0 1 0"/>
    <origin xyz="-0.6 -0.6 -0.5"/>
    <parent link="base"/>
    <child link="rb_link"/>
  </joint>
</robot>

