<?xml version="1.0" ?>
<!-- =================================================================================== -->
<!-- |    This document was autogenerated by xacro from sample.xacro                   | -->
<!-- |    EDITING THIS FILE BY HAND IS NOT RECOMMENDED                                 | -->
<!-- =================================================================================== -->
<robot name="veerbhadra" xmlns:controller="http://playerstage.sourceforge.net/gazebo/xmlschema/#controller" xmlns:interface="http://playerstage.sourceforge.net/gazebo/xmlschema/#interface" xmlns:sensor="http://playerstage.sourceforge.net/gazebo/xmlschema/#sensor" xmlns:xacro="http://www.ros.org/wiki/xacro">
  <!-- The Frame and its Joint with the World -->
  <link name="base">
    <visual>
      <origin xyz="0 0 0"/>
      <geometry>
        <box size="1.5 1.0 0.2"/>
      </geometry>
      <material name="white">
        <color rgba="1 1 1 1"/>
      </material>
    </visual>
    <collision>
      <origin xyz="0 0 0"/>
      <geometry>
        <box size="1.5 1.0 0.2"/>
      </geometry>
    </collision>
    <inertial>
      <origin xyz="0 0 0"/>
      <mass value="1.0"/>
      <inertia ixx="1.0" ixy="0.0" ixz="0.0" iyy="1.0" iyz="0.0" izz="1.0"/>
    </inertial>
  </link>
  <gazebo reference="base">
    <material>Gazebo/White</material>
  </gazebo>
  <!-- The Head and its Joint with the Frame -->
  <link name="head">
    <visual>
      <origin xyz="0 0 0.1"/>
      <geometry>
        <box size="0.2 0.2 0.2"/>
      </geometry>
      <material name="green">
        <color rgba="0 1 0 1"/>
      </material>
    </visual>
    <collision>
      <origin xyz="0 0 0.1"/>
      <geometry>
        <box size="0.2 0.2 0.2"/>
      </geometry>
    </collision>
    <inertial>
      <origin xyz="0 0 0.1"/>
      <mass value="1.0"/>
      <inertia ixx="1.0" ixy="0.0" ixz="0.0" iyy="1.0" iyz="0.0" izz="1.0"/>
    </inertial>
  </link>
  <joint name="head_joint" type="fixed">
    <origin xyz="0.65 0 0.1"/>
    <parent link="base"/>
    <child link="head"/>
  </joint>
  <gazebo reference="head">
    <material>Gazebo/Green</material>
  </gazebo>
  <!-- The Wheel macro -->
  <!-- use the Wheel xacro to create the wheels -->
  <link name="lf_link">
    <visual>
      <origin rpy="1.57075 0 0" xyz="0 0 0"/>
      <geometry>
        <cylinder length="0.1" radius="0.2"/>
      </geometry>
      <material name="red">
        <color rgba="1 0 0 1"/>
      </material>
    </visual>
    <collision>
      <origin rpy="1.57075 0 0" xyz="0 0 0"/>
      <geometry>
        <cylinder length="0.1" radius="0.2"/>
      </geometry>
    </collision>
    <inertial>
      <mass value="1.0"/>
      <inertia ixx="1.0" ixy="0.0" ixz="0.0" iyy="1.0" iyz="0.0" izz="1.0"/>
    </inertial>
  </link>
  <gazebo reference="lf_link">
    <material>Gazebo/Red</material>
    <mu1 value="1.0"/>
    <mu2 value="1.0"/>
  </gazebo>
  <joint name="lf_joint" type="continuous">
    <axis xyz="0 1 0"/>
    <origin xyz="0.6 0.6 -0.5"/>
    <parent link="base"/>
    <child link="lf_link"/>
  </joint>
  <link name="lb_link">
    <visual>
      <origin rpy="1.57075 0 0" xyz="0 0 0"/>
      <geometry>
        <cylinder length="0.1" radius="0.2"/>
      </geometry>
      <material name="red">
        <color rgba="1 0 0 1"/>
      </material>
    </visual>
    <collision>
      <origin rpy="1.57075 0 0" xyz="0 0 0"/>
      <geometry>
        <cylinder length="0.1" radius="0.2"/>
      </geometry>
    </collision>
    <inertial>
      <mass value="1.0"/>
      <inertia ixx="1.0" ixy="0.0" ixz="0.0" iyy="1.0" iyz="0.0" izz="1.0"/>
    </inertial>
  </link>
  <gazebo reference="lb_link">
    <material>Gazebo/Red</material>
    <mu1 value="1.0"/>
    <mu2 value="1.0"/>
  </gazebo>
  <joint name="lb_joint" type="continuous">
    <axis xyz="0 1 0"/>
    <origin xyz="-0.6 0.6 -0.5"/>
    <parent link="base"/>
    <child link="lb_link"/>
  </joint>
  <link name="rf_link">
    <visual>
      <origin rpy="1.57075 0 0" xyz="0 0 0"/>
      <geometry>
        <cylinder length="0.1" radius="0.2"/>
      </geometry>
      <material name="red">
        <color rgba="1 0 0 1"/>
      </material>
    </visual>
    <collision>
      <origin rpy="1.57075 0 0" xyz="0 0 0"/>
      <geometry>
        <cylinder length="0.1" radius="0.2"/>
      </geometry>
    </collision>
    <inertial>
      <mass value="1.0"/>
      <inertia ixx="1.0" ixy="0.0" ixz="0.0" iyy="1.0" iyz="0.0" izz="1.0"/>
    </inertial>
  </link>
  <gazebo reference="rf_link">
    <material>Gazebo/Red</material>
    <mu1 value="1.0"/>
    <mu2 value="1.0"/>
  </gazebo>
  <joint name="rf_joint" type="continuous">
    <axis xyz="0 1 0"/>
    <origin xyz="0.6 -0.6 -0.5"/>
    <parent link="base"/>
    <child link="rf_link"/>
  </joint>
  <link name="rb_link">
    <visual>
      <origin rpy="1.57075 0 0" xyz="0 0 0"/>
      <geometry>
        <cylinder length="0.1" radius="0.2"/>
      </geometry>
      <material name="red">
        <color rgba="1 0 0 1"/>
      </material>
    </visual>
    <collision>
      <origin rpy="1.57075 0 0" xyz="0 0 0"/>
      <geometry>
        <cylinder length="0.1" radius="0.2"/>
      </geometry>
    </collision>
    <inertial>
      <mass value="1.0"/>
      <inertia ixx="1.0" ixy="0.0" ixz="0.0" iyy="1.0" iyz="0.0" izz="1.0"/>
    </inertial>
  </link>
  <gazebo reference="rb_link">
    <material>Gazebo/Red</material>
    <mu1 value="1.0"/>
    <mu2 value="1.0"/>
  </gazebo>
  <joint name="rb_joint" type="continuous">
    <axis xyz="0 1 0"/>
    <origin xyz="-0.6 -0.6 -0.5"/>
    <parent link="base"/>
    <child link="rb_link"/>
  </joint>
  <gazebo>
    <controller:diffdrive_plugin name="differential_drive_controller" plugin="libdiffdrive_plugin.so">
      <alwaysOn>true</alwaysOn>
      <update>100</update>
      <updateRate>100.0</updateRate>
      <leftJoint>lb_joint</leftJoint>
      <rightJoint>rb_joint</rightJoint>
      <wheelSeparation>0.6</wheelSeparation>
      <wheelDiameter>0.4</wheelDiameter>
      <torque>5</torque>
      <interface:position name="auv"/>
      <topicName>cmd_vel</topicName>
    </controller:diffdrive_plugin>
    <controller:gazebo_ros_controller_manager name="gazebo_ros_controller_manager" plugin="libgazebo_ros_controller_manager.so">
      <alwaysOn>true</alwaysOn>
      <updateRate>100.0</updateRate>
      <interface:audio name="gazebo_ros_controller_manager_dummy_iface"/>
    </controller:gazebo_ros_controller_manager>
  </gazebo>
</robot>

